<?xml version="1.0" ?>
<robot name="eric_bot" xmlns:xacro="http://www.ros.org/wiki/xacro">

<xacro:include filename="$(find eric_bot_description)/urdf/materials.xacro" />
<xacro:include filename="$(find eric_bot_description)/urdf/eric_bot.trans" />
<xacro:include filename="$(find eric_bot_description)/urdf/eric_bot.gazebo" />
<link name="base_link">
  <inertial>
    <origin xyz="-0.23713528803949824 -0.13426975337040928 0.15351805277851321" rpy="0 0 0"/>
    <mass value="5.5523268218185935"/>
    <inertia ixx="0.159006" iyy="0.128806" izz="0.266255" ixy="0.000336" iyz="-0.010472" ixz="0.00017"/>
  </inertial>
  <visual>
    <origin xyz="0 0 0" rpy="0 0 0"/>
    <geometry>
      <mesh filename="file://$(find eric_bot_description)/meshes/base_link.stl" scale="0.001 0.001 0.001"/>
    </geometry>
    <material name="silver"/>
  </visual>
  <collision>
    <origin xyz="0 0 0" rpy="0 0 0"/>
    <geometry>
      <mesh filename="file://$(find eric_bot_description)/meshes/base_link.stl" scale="0.001 0.001 0.001"/>
    </geometry>
  </collision>
</link>

<link name="lidar_1">
  <inertial>
    <origin xyz="0.0 -3.045630598899618e-07 0.015000000000000013" rpy="0 0 0"/>
    <mass value="0.39442724222286785"/>
    <inertia ixx="0.000349" iyy="0.000349" izz="0.00064" ixy="0.0" iyz="-0.0" ixz="-0.0"/>
  </inertial>
  <visual>
    <origin xyz="0.2375 0.049335 -0.255" rpy="0 0 0"/>
    <geometry>
      <mesh filename="file://$(find eric_bot_description)/meshes/lidar_1.stl" scale="0.001 0.001 0.001"/>
    </geometry>
    <material name="silver"/>
  </visual>
  <collision>
    <origin xyz="0.2375 0.049335 -0.255" rpy="0 0 0"/>
    <geometry>
      <mesh filename="file://$(find eric_bot_description)/meshes/lidar_1.stl" scale="0.001 0.001 0.001"/>
    </geometry>
  </collision>
</link>

<link name="gps_1">
  <inertial>
    <origin xyz="-4.996003610813204e-16 -0.19000030456305989 0.002499999999999891" rpy="0 0 0"/>
    <mass value="0.03225"/>
    <inertia ixx="7e-06" iyy="2.7e-05" izz="3.4e-05" ixy="0.0" iyz="0.0" ixz="0.0"/>
  </inertial>
  <visual>
    <origin xyz="0.2375 0.049335 -0.175" rpy="0 0 0"/>
    <geometry>
      <mesh filename="file://$(find eric_bot_description)/meshes/gps_1.stl" scale="0.001 0.001 0.001"/>
    </geometry>
    <material name="silver"/>
  </visual>
  <collision>
    <origin xyz="0.2375 0.049335 -0.175" rpy="0 0 0"/>
    <geometry>
      <mesh filename="file://$(find eric_bot_description)/meshes/gps_1.stl" scale="0.001 0.001 0.001"/>
    </geometry>
  </collision>
</link>

<link name="imu_1">
  <inertial>
    <origin xyz="-2.498001805406602e-16 -0.27500030456305935 0.0025000000000001132" rpy="0 0 0"/>
    <mass value="0.016125"/>
    <inertia ixx="3e-06" iyy="3e-06" izz="7e-06" ixy="0.0" iyz="-0.0" ixz="-0.0"/>
  </inertial>
  <visual>
    <origin xyz="0.2375 0.049335 -0.175" rpy="0 0 0"/>
    <geometry>
      <mesh filename="file://$(find eric_bot_description)/meshes/imu_1.stl" scale="0.001 0.001 0.001"/>
    </geometry>
    <material name="silver"/>
  </visual>
  <collision>
    <origin xyz="0.2375 0.049335 -0.175" rpy="0 0 0"/>
    <geometry>
      <mesh filename="file://$(find eric_bot_description)/meshes/imu_1.stl" scale="0.001 0.001 0.001"/>
    </geometry>
  </collision>
</link>

<link name="right_caster_1">
  <inertial>
    <origin xyz="0.1199999999999996 0.0 -0.015000000000000041" rpy="0 0 0"/>
    <mass value="1.1380105228363668"/>
    <inertia ixx="0.000472" iyy="0.000472" izz="0.000728" ixy="0.0" iyz="0.0" ixz="0.0"/>
  </inertial>
  <visual>
    <origin xyz="0.235 0.3 -0.04" rpy="0 0 0"/>
    <geometry>
      <mesh filename="file://$(find eric_bot_description)/meshes/right_caster_1.stl" scale="0.001 0.001 0.001"/>
    </geometry>
    <material name="silver"/>
  </visual>
  <collision>
    <origin xyz="0.235 0.3 -0.04" rpy="0 0 0"/>
    <geometry>
      <mesh filename="file://$(find eric_bot_description)/meshes/right_caster_1.stl" scale="0.001 0.001 0.001"/>
    </geometry>
  </collision>
</link>

<link name="left_caster_1">
  <inertial>
    <origin xyz="-0.12 0.0 -0.014999999999999989" rpy="0 0 0"/>
    <mass value="1.1380105228363662"/>
    <inertia ixx="0.000472" iyy="0.000472" izz="0.000728" ixy="-0.0" iyz="-0.0" ixz="-0.0"/>
  </inertial>
  <visual>
    <origin xyz="0.235 0.3 -0.04" rpy="0 0 0"/>
    <geometry>
      <mesh filename="file://$(find eric_bot_description)/meshes/left_caster_1.stl" scale="0.001 0.001 0.001"/>
    </geometry>
    <material name="silver"/>
  </visual>
  <collision>
    <origin xyz="0.235 0.3 -0.04" rpy="0 0 0"/>
    <geometry>
      <mesh filename="file://$(find eric_bot_description)/meshes/left_caster_1.stl" scale="0.001 0.001 0.001"/>
    </geometry>
  </collision>
</link>

<link name="left_wheel_1">
  <inertial>
    <origin xyz="0.03991962077493816 -2.6157730081342715e-15 0.0" rpy="0 0 0"/>
    <mass value="1.771999628294055"/>
    <inertia ixx="0.010694" iyy="0.00572" izz="0.00572" ixy="-0.0" iyz="-0.0" ixz="0.0"/>
  </inertial>
  <visual>
    <origin xyz="0.005 -0.0 -0.11" rpy="0 0 0"/>
    <geometry>
      <mesh filename="file://$(find eric_bot_description)/meshes/left_wheel_1.stl" scale="0.001 0.001 0.001"/>
    </geometry>
    <material name="silver"/>
  </visual>
  <collision>
    <origin xyz="0.005 -0.0 -0.11" rpy="0 0 0"/>
    <geometry>
      <mesh filename="file://$(find eric_bot_description)/meshes/left_wheel_1.stl" scale="0.001 0.001 0.001"/>
    </geometry>
  </collision>
</link>

<link name="right_wheel_1">
  <inertial>
    <origin xyz="-0.03991962077493816 -8.630141603479498e-15 -1.3877787807814457e-17" rpy="0 0 0"/>
    <mass value="1.7719996282940542"/>
    <inertia ixx="0.010694" iyy="0.00572" izz="0.00572" ixy="0.0" iyz="-0.0" ixz="0.0"/>
  </inertial>
  <visual>
    <origin xyz="0.47 -0.0 -0.11" rpy="0 0 0"/>
    <geometry>
      <mesh filename="file://$(find eric_bot_description)/meshes/right_wheel_1.stl" scale="0.001 0.001 0.001"/>
    </geometry>
    <material name="silver"/>
  </visual>
  <collision>
    <origin xyz="0.47 -0.0 -0.11" rpy="0 0 0"/>
    <geometry>
      <mesh filename="file://$(find eric_bot_description)/meshes/right_wheel_1.stl" scale="0.001 0.001 0.001"/>
    </geometry>
  </collision>
</link>

<joint name="lidar_link" type="fixed">
  <origin xyz="-0.2375 -0.049335 0.255" rpy="0 0 0"/>
  <parent link="base_link"/>
  <child link="lidar_1"/>
</joint>

<joint name="gps_link" type="fixed">
  <origin xyz="-0.2375 -0.049335 0.175" rpy="0 0 0"/>
  <parent link="base_link"/>
  <child link="gps_1"/>
</joint>

<joint name="imu_link" type="fixed">
  <origin xyz="-0.2375 -0.049335 0.175" rpy="0 0 0"/>
  <parent link="base_link"/>
  <child link="imu_1"/>
</joint>

<joint name="caster_link_1" type="fixed">
  <origin xyz="-0.235 -0.3 0.04" rpy="0 0 0"/>
  <parent link="base_link"/>
  <child link="right_caster_1"/>
</joint>

<joint name="caster_link_2" type="fixed">
  <origin xyz="-0.235 -0.3 0.04" rpy="0 0 0"/>
  <parent link="base_link"/>
  <child link="left_caster_1"/>
</joint>

<joint name="left_wheel_joint" type="continuous">
  <origin xyz="-0.005 0.0 0.11" rpy="0 0 0"/>
  <parent link="base_link"/>
  <child link="left_wheel_1"/>
  <axis xyz="-1.0 0.0 0.0"/>
</joint>

<joint name="right_wheel_joint" type="continuous">
  <origin xyz="-0.47 0.0 0.11" rpy="0 0 0"/>
  <parent link="base_link"/>
  <child link="right_wheel_1"/>
  <axis xyz="1.0 0.0 0.0"/>
</joint>

</robot>
